Workbook

Sheet Data
A1: Symbol | B1: Issuer Name | C1: Required Yield (IRR) | D1: Annualised Required Yield (IRR) | F1: Ask Price | G1: Currency | H1: Face Value/ Maturity Value | J1: Volume | M1: Coupon | N1: Issue Date | O1: Maturity | P1: Term (In Years) | Q1: Coupon Yield | R1: Frequency (Yearly) | S1: Frequency (Period) | U1: No. of coupons | V1: Coupon Amount (INR) | W1: IRR | X1: Yield (Annual) | Y1: Macaulay Duration in Years | Z1: Modified Duration in Years | AA1: Dollar Duration | AB1: Bond Type | AC1: Country | AD1: Yearly Payment Frequency
A3: 10BML25 | B3: Belstar Microfinance Ltd. | C3: =RATE(U3,V3,-F3,H3) -> 0.39761212 | D3: =C3*AD3 -> 1.5904485 | F3: 12724.84 | G3: INR | H3: 100000 | J3: 10 | M3: 0.1 | N3: 45139 | O3: 45870 | P3: =ROUND(YEARFRAC(N3,O3),0) -> 2 | Q3: =(M3*H3)/F3 -> 0.7858645 | R3: =IF(S3="Quarterly",4,IF(S3="Semi-annual",2,IF(S3="Annual",1,IF(S3="Pays at maturity",0,IF(S3="Monthly",12,0))))) -> 4 | S3: Quarterly | U3: =R3*P3 -> 8 | V3: =(H3*M3)/AD3 -> 2500 | Y3: =DURATION(N3,O3,M3,D3,AD3) -> 1.4161488 | Z3: =Y3/(1+C3) -> 1.0132631 | AA3: =-Z3*F3 -> -12893.611 | AB3: None | AC3: India | AD3: =_xlfn.SWITCH(PROPER(TRIM(S3)), "Annual",1, "Semi-Annual",2, "Quarterly",4, "Monthly",12, "") -> 4
A4: 85KFL25 | B4: Kosamattam Finance Ltd. | C4: =RATE(U4,V4,-F4,H4) -> 0.08584701 | D4: =C4*AD4 -> 0.08584701 | F4: 997.84 | G4: INR | H4: 1000 | J4: 220 | L4: 11.444721 | M4: 0.085 | N4: 44784 | O4: 45879 | P4: =ROUND(YEARFRAC(N4,O4),0) -> 3 | Q4: =(M4*H4)/F4 -> 0.085183997 | R4: =IF(S4="Quarterly",4,IF(S4="Semi-annual",2,IF(S4="Annual",1,IF(S4="Pays at maturity",0,IF(S4="Monthly",12,0))))) -> 1 | S4: Annual | U4: =R4*P4 -> 3 | V4: =(H4*M4)/AD4 -> 85 | W4: =RATE(U4,V4,-F4,H4) -> 0.08584701 | X4: =W4*AD4 -> 0.08584701 | Y4: =DURATION(N4,O4,M4,D4,AD4) -> 2.7680764 | Z4: =Y4/(1+C4) -> 2.5492324 | AA4: =-Z4*F4 -> -2543.726 | AB4: None | AC4: India | AD4: =_xlfn.SWITCH(PROPER(TRIM(S4)), "Annual",1, "Semi-Annual",2, "Quarterly",4, "Monthly",12, "") -> 1
A6: 950CCIL25 | B6: Chemmanur Credits & Investments Ltd. | C6: =RATE(U6,V6,-F6,H6) -> 0.095 | D6: =C6*AD6 -> 0.095 | F6: 1000 | G6: INR | H6: 1000 | J6: 100 | L6: 9.5 | M6: 0.095 | N6: 45518 | O6: 45884 | P6: =ROUND(YEARFRAC(N6,O6),0) -> 1 | Q6: =(M6*H6)/F6 -> 0.095 | R6: =IF(S6="Quarterly",4,IF(S6="Semi-annual",2,IF(S6="Annual",1,IF(S6="Pays at maturity",0,IF(S6="Monthly",12,0))))) -> 1 | S6: Annual | U6: =R6*P6 -> 1 | V6: =(H6*M6)/AD6 -> 95 | W6: =RATE(U6,V6,-F6,H6) -> 0.095 | X6: =W6*AD6 -> 0.095 | Y6: =DURATION(N6,O6,M6,D6,AD6) -> 0.91601979 | Z6: =Y6/(1+C6) -> 0.83654775 | AA6: =-Z6*F6 -> -836.54775 | AB6: None | AC6: India | AD6: =_xlfn.SWITCH(PROPER(TRIM(S6)), "Annual",1, "Semi-Annual",2, "Quarterly",4, "Monthly",12, "") -> 1
A8: 934WBSE25 | B8: West Bengal State Electricity Distribution Co. Ltd. | C8: =RATE(U8,V8,-F8,H8) -> 0.0467 | D8: =C8*AD8 -> 0.0934 | F8: 1000000 | G8: INR | H8: 1000000 | J8: 1 | M8: 0.0934 | N8: 40406 | O8: 45885 | P8: =ROUND(YEARFRAC(N8,O8),0) -> 15 | Q8: =(M8*H8)/F8 -> 0.0934 | R8: =IF(S8="Quarterly",4,IF(S8="Semi-annual",2,IF(S8="Annual",1,IF(S8="Pays at maturity",0,IF(S8="Monthly",12,0))))) -> 2 | S8: Semi-annual | U8: =R8*P8 -> 30 | V8: =(H8*M8)/AD8 -> 46700 | W8: =RATE(U8,V8,-F8,H8) -> 0.0467 | X8: =W8*AD8 -> 0.0934 | Y8: =DURATION(N8,O8,M8,D8,AD8) -> 8.3568759 | Z8: =Y8/(1+C8) -> 7.9840221 | AA8: =-Z8*F8 -> -7984022.1 | AB8: None | AC8: India | AD8: =_xlfn.SWITCH(PROPER(TRIM(S8)), "Annual",1, "Semi-Annual",2, "Quarterly",4, "Monthly",12, "") -> 2
A9: 1075NBSL25 | B9: Nirmal Bang Securities Pvt Ltd. | C9: =RATE(U9,V9,-F9,H9) -> 0.026540883 | D9: =C9*AD9 -> 0.10616353 | F9: 100238 | G9: INR | H9: 100000 | J9: 5 | M9: 0.1075 | N9: 45342 | O9: 45889 | P9: =ROUND(YEARFRAC(N9,O9),0) -> 2 | Q9: =(M9*H9)/F9 -> 0.10724476 | R9: =IF(S9="Quarterly",4,IF(S9="Semi-annual",2,IF(S9="Annual",1,IF(S9="Pays at maturity",0,IF(S9="Monthly",12,0))))) -> 4 | S9: Quarterly | U9: =R9*P9 -> 8 | V9: =(H9*M9)/AD9 -> 2687.5 | W9: =RATE(U9,V9,-F9,H9) -> 0.026540883 | X9: =W9*AD9 -> 0.10616353 | Y9: =DURATION(N9,O9,M9,D9,AD9) -> 1.4053172 | Z9: =Y9/(1+C9) -> 1.3689832 | AA9: =-Z9*F9 -> -137224.14 | AB9: Callable | AC9: India | AD9: =_xlfn.SWITCH(PROPER(TRIM(S9)), "Annual",1, "Semi-Annual",2, "Quarterly",4, "Monthly",12, "") -> 4
A10: 715NTPC25 | B10: Ntpc Ltd. | C10: =RATE(U10,V10,-F10,H10) -> 0.057215909 | D10: =C10*AD10 -> 0.057215909 | F10: 1106532.9 | G10: INR | H10: 1000000 | J10: 8 | L10: 3.4759956 | M10: 0.0715 | N10: 42237 | O10: 45890 | P10: =ROUND(YEARFRAC(N10,O10),0) -> 10 | Q10: =(M10*H10)/F10 -> 0.064616244 | R10: =IF(S10="Quarterly",4,IF(S10="Semi-annual",2,IF(S10="Annual",1,IF(S10="Pays at maturity",0,IF(S10="Monthly",12,0))))) -> 1 | S10: Annual | U10: =R10*P10 -> 10 | V10: =(H10*M10)/AD10 -> 71500 | W10: =RATE(U10,V10,-F10,H10) -> 0.057215909 | X10: =W10*AD10 -> 0.057215909 | Y10: =DURATION(N10,O10,M10,D10,AD10) -> 7.6113042 | Z10: =Y10/(1+C10) -> 7.1993849 | AA10: =-Z10*F10 -> -7966356.2 | AB10: None | AC10: India | AD10: =_xlfn.SWITCH(PROPER(TRIM(S10)), "Annual",1, "Semi-Annual",2, "Quarterly",4, "Monthly",12, "") -> 1
A11: 715IRFC25 | B11: Indian Railway Finance Corp. Ltd. | C11: =RATE(U11,V11,-F11,H11) -> 0.060599662 | D11: =C11*AD11 -> 0.060599662 | F11: 1080000 | G11: INR | H11: 1000000 | J11: 7 | L11: 0.8432257 | M11: 0.0715 | N11: 42237 | O11: 45890 | P11: =ROUND(YEARFRAC(N11,O11),0) -> 10 | Q11: =(M11*H11)/F11 -> 0.066203704 | R11: =IF(S11="Quarterly",4,IF(S11="Semi-annual",2,IF(S11="Annual",1,IF(S11="Pays at maturity",0,IF(S11="Monthly",12,0))))) -> 1 | S11: Annual | U11: =R11*P11 -> 10 | V11: =(H11*M11)/AD11 -> 71500 | W11: =RATE(U11,V11,-F11,H11) -> 0.060599662 | X11: =W11*AD11 -> 0.060599662 | Y11: =DURATION(N11,O11,M11,D11,AD11) -> 7.5790461 | Z11: =Y11/(1+C11) -> 7.1460009 | AA11: =-Z11*F11 -> -7717681 | AB11: None | AC11: India | AD11: =_xlfn.SWITCH(PROPER(TRIM(S11)), "Annual",1, "Semi-Annual",2, "Quarterly",4, "Monthly",12, "") -> 1
A12: 990VCL25 | B12: Vivriti Capital Pvt Ltd. | C12: =RATE(U12,V12,-F12,H12) -> 0.026058789 | D12: =C12*AD12 -> 0.10423516 | F12: 99508.89 | G12: INR | H12: 100000 | J12: 1 | M12: 0.099 | N12: 45463 | O12: 45891 | P12: =ROUND(YEARFRAC(N12,O12),0) -> 1 | Q12: =(M12*H12)/F12 -> 0.099488598 | R12: =IF(S12="Quarterly",4,IF(S12="Semi-annual",2,IF(S12="Annual",1,IF(S12="Pays at maturity",0,IF(S12="Monthly",12,0))))) -> 4 | S12: Quarterly | U12: =R12*P12 -> 4 | V12: =(H12*M12)/AD12 -> 2475 | W12: =RATE(U12,V12,-F12,H12) -> 0.026058789 | X12: =W12*AD12 -> 0.10423516 | Y12: =DURATION(N12,O12,M12,D12,AD12) -> 1.1130723 | Z12: =Y12/(1+C12) -> 1.0848036 | AA12: =-Z12*F12 -> -107947.6 | AB12: None | AC12: India | AD12: =_xlfn.SWITCH(PROPER(TRIM(S12)), "Annual",1, "Semi-Annual",2, "Quarterly",4, "Monthly",12, "") -> 4
A14: 950AFL25 | B14: Aye Finance Ltd. | C14: =RATE(U14,V14,-F14,H14) -> 0.095 | D14: =C14*AD14 -> 0.095 | F14: 100000 | G14: INR | H14: 100000 | J14: 1 | L14: 9.5 | M14: 0.095 | N14: 45345 | O14: 45892 | P14: =ROUND(YEARFRAC(N14,O14),0) -> 2 | Q14: =(M14*H14)/F14 -> 0.095 | R14: =IF(S14="Quarterly",4,IF(S14="Semi-annual",2,IF(S14="Annual",1,IF(S14="Pays at maturity",0,IF(S14="Monthly",12,0))))) -> 1 | S14: Annual | U14: =R14*P14 -> 2 | V14: =(H14*M14)/AD14 -> 9500 | W14: =RATE(U14,V14,-F14,H14) -> 0.095 | X14: =W14*AD14 -> 0.095 | Y14: =DURATION(N14,O14,M14,D14,AD14) -> 1.413242 | Z14: =Y14/(1+C14) -> 1.290632 | AA14: =-Z14*F14 -> -129063.2 | AB14: None | AC14: India | AD14: =_xlfn.SWITCH(PROPER(TRIM(S14)), "Annual",1, "Semi-Annual",2, "Quarterly",4, "Monthly",12, "") -> 1
A15: 1255NEO25 | B15: NeoGrowth Credit Pvt Ltd. | C15: =RATE(U15,V15,-F15,H15) -> 0.19017603 | D15: =C15*AD15 -> 0.19017603 | F15: 90000 | G15: INR | H15: 100000 | J15: 1 | L15: 23.811976 | M15: 0.1255 | N15: 45286 | O15: 45895 | P15: =ROUND(YEARFRAC(N15,O15),0) -> 2 | Q15: =(M15*H15)/F15 -> 0.13944444 | R15: =IF(S15="Quarterly",4,IF(S15="Semi-annual",2,IF(S15="Annual",1,IF(S15="Pays at maturity",0,IF(S15="Monthly",12,0))))) -> 1 | S15: Annual | U15: =R15*P15 -> 2 | V15: =(H15*M15)/AD15 -> 12550 | W15: =RATE(U15,V15,-F15,H15) -> 0.19017603 | X15: =W15*AD15 -> 0.19017603 | Y15: =DURATION(N15,O15,M15,D15,AD15) -> 1.5495038 | Z15: =Y15/(1+C15) -> 1.3019114 | AA15: =-Z15*F15 -> -117172.03 | AB15: Putable | AC15: India | AD15: =_xlfn.SWITCH(PROPER(TRIM(S15)), "Annual",1, "Semi-Annual",2, "Quarterly",4, "Monthly",12, "") -> 1
A16: 1025UCL25 | B16: Ugro Capital Ltd. | C16: =RATE(U16,V16,-F16,H16) -> 0.10338558 | D16: =C16*AD16 -> 0.10338558 | F16: 998.47 | G16: INR | H16: 1000 | J16: 1 | L16: 11.863723 | M16: 0.1025 | N16: 45349 | O16: 45896 | P16: =ROUND(YEARFRAC(N16,O16),0) -> 2 | Q16: =(M16*H16)/F16 -> 0.10265707 | R16: =IF(S16="Quarterly",4,IF(S16="Semi-annual",2,IF(S16="Annual",1,IF(S16="Pays at maturity",0,IF(S16="Monthly",12,0))))) -> 1 | S16: Annual | U16: =R16*P16 -> 2 | V16: =(H16*M16)/AD16 -> 102.5 | W16: =RATE(U16,V16,-F16,H16) -> 0.10338558 | X16: =W16*AD16 -> 0.10338558 | Y16: =DURATION(N16,O16,M16,D16,AD16) -> 1.4069617 | Z16: =Y16/(1+C16) -> 1.2751315 | AA16: =-Z16*F16 -> -1273.1806 | AB16: None | AC16: India | AD16: =_xlfn.SWITCH(PROPER(TRIM(S16)), "Annual",1, "Semi-Annual",2, "Quarterly",4, "Monthly",12, "") -> 1
A17: 1075UCL25 | B17: Ugro Capital Ltd. | C17: =RATE(U17,V17,-F17,H17) -> 0.085164418 | D17: =C17*AD17 -> 0.085164418 | F17: 1039.55 | G17: INR | H17: 1000 | J17: 4 | L17: -19.204811 | M17: 0.1075 | N17: 45349 | O17: 45896 | P17: =ROUND(YEARFRAC(N17,O17),0) -> 2 | Q17: =(M17*H17)/F17 -> 0.10341013 | R17: =IF(S17="Quarterly",4,IF(S17="Semi-annual",2,IF(S17="Annual",1,IF(S17="Pays at maturity",0,IF(S17="Monthly",12,0))))) -> 1 | S17: Annual | U17: =R17*P17 -> 2 | V17: =(H17*M17)/AD17 -> 107.5 | W17: =RATE(U17,V17,-F17,H17) -> 0.085164418 | X17: =W17*AD17 -> 0.085164418 | Y17: =DURATION(N17,O17,M17,D17,AD17) -> 1.4047056 | Z17: =Y17/(1+C17) -> 1.2944633 | AA17: =-Z17*F17 -> -1345.6594 | AB17: None | AC17: India | AD17: =_xlfn.SWITCH(PROPER(TRIM(S17)), "Annual",1, "Semi-Annual",2, "Quarterly",4, "Monthly",12, "") -> 1
A18: 001CSSL25 | B18: Creixent Special Steels Ltd. | C18: =RATE(U18,V18,-F18,H18) -> -0.051132153 | D18: =C18*AD18 -> -0.051132153 | F18: 1444844 | G18: INR | H18: 1000000 | J18: 1863 | L18: -8.1778983 | M18: 0.0001 | N18: 43340 | O18: 45897 | P18: =ROUND(YEARFRAC(N18,O18),0) -> 7 | Q18: =(M18*H18)/F18 -> 6.9211624e-05 | R18: =IF(S18="Quarterly",4,IF(S18="Semi-annual",2,IF(S18="Annual",1,IF(S18="Pays at maturity",0,IF(S18="Monthly",12,0))))) -> 1 | S18: Annual | U18: =R18*P18 -> 7 | V18: =(H18*M18)/AD18 -> 100 | W18: =RATE(U18,V18,-F18,H18) -> -0.051132153 | X18: =W18*AD18 -> -0.051132153 | Y18: =DURATION(N18,O18,M18,D18,AD18) -> #NUM! | Z18: =Y18/(1+C18) -> #NUM! | AA18: =-Z18*F18 -> #NUM! | AB18: None | AC18: India | AD18: =_xlfn.SWITCH(PROPER(TRIM(S18)), "Annual",1, "Semi-Annual",2, "Quarterly",4, "Monthly",12, "") -> 1
A19: 10SFL25 | B19: Sakthi Finance Ltd. | C19: =RATE(U19,V19,-F19,H19) -> 0.10208836 | D19: =C19*AD19 -> 0.10208836 | F19: 993.41 | G19: INR | H19: 1000 | J19: 17 | L19: 12.051015 | M19: 0.1 | N19: 44406 | O19: 45898 | P19: =ROUND(YEARFRAC(N19,O19),0) -> 4 | Q19: =(M19*H19)/F19 -> 0.10066337 | R19: =IF(S19="Quarterly",4,IF(S19="Semi-annual",2,IF(S19="Annual",1,IF(S19="Pays at maturity",0,IF(S19="Monthly",12,0))))) -> 1 | S19: Annual | U19: =R19*P19 -> 4 | V19: =(H19*M19)/AD19 -> 100 | W19: =RATE(U19,V19,-F19,H19) -> 0.10208836 | X19: =W19*AD19 -> 0.10208836 | Y19: =DURATION(N19,O19,M19,D19,AD19) -> 3.2496304 | Z19: =Y19/(1+C19) -> 2.9486115 | AA19: =-Z19*F19 -> -2929.1802 | AB19: None | AC19: India | AD19: =_xlfn.SWITCH(PROPER(TRIM(S19)), "Annual",1, "Semi-Annual",2, "Quarterly",4, "Monthly",12, "") -> 1
A21: 1085SFL25 | B21: Satin Finserv Ltd. | C21: =RATE(U21,V21,-F21,H21) -> 0.11319127 | D21: =C21*AD21 -> 0.11319127 | F21: 99200 | G21: INR | H21: 100000 | J21: 3 | L21: 14.483944 | M21: 0.1085 | N21: 45355 | O21: 45904 | P21: =ROUND(YEARFRAC(N21,O21),0) -> 2 | Q21: =(M21*H21)/F21 -> 0.109375 | R21: =IF(S21="Quarterly",4,IF(S21="Semi-annual",2,IF(S21="Annual",1,IF(S21="Pays at maturity",0,IF(S21="Monthly",12,0))))) -> 1 | S21: Annual | U21: =R21*P21 -> 2 | V21: =(H21*M21)/AD21 -> 10850 | W21: =RATE(U21,V21,-F21,H21) -> 0.11319127 | X21: =W21*AD21 -> 0.11319127 | Y21: =DURATION(N21,O21,M21,D21,AD21) -> 1.4017464 | Z21: =Y21/(1+C21) -> 1.2592144 | AA21: =-Z21*F21 -> -124914.07 | AB21: None | AC21: India | AD21: =_xlfn.SWITCH(PROPER(TRIM(S21)), "Annual",1, "Semi-Annual",2, "Quarterly",4, "Monthly",12, "") -> 1
A22: 1050VCL25 | B22: Vivriti Capital Pvt Ltd. | C22: =RATE(U22,V22,-F22,H22) -> 0.061183405 | D22: =C22*AD22 -> 0.061183405 | F22: 1080.2 | G22: INR | H22: 1000 | J22: 9 | L22: -50.500936 | M22: 0.105 | N22: 45175 | O22: 45906 | P22: =ROUND(YEARFRAC(N22,O22),0) -> 2 | Q22: =(M22*H22)/F22 -> 0.097204221 | R22: =IF(S22="Quarterly",4,IF(S22="Semi-annual",2,IF(S22="Annual",1,IF(S22="Pays at maturity",0,IF(S22="Monthly",12,0))))) -> 1 | S22: Annual | U22: =R22*P22 -> 2 | V22: =(H22*M22)/AD22 -> 105 | W22: =RATE(U22,V22,-F22,H22) -> 0.061183405 | X22: =W22*AD22 -> 0.061183405 | Y22: =DURATION(N22,O22,M22,D22,AD22) -> 1.9084002 | Z22: =Y22/(1+C22) -> 1.7983698 | AA22: =-Z22*F22 -> -1942.599 | AB22: None | AC22: India | AD22: =_xlfn.SWITCH(PROPER(TRIM(S22)), "Annual",1, "Semi-Annual",2, "Quarterly",4, "Monthly",12, "") -> 1
A23: 1003VCL25 | B23: Vivriti Capital Pvt Ltd. | C23: =RATE(U23,V23,-F23,H23) -> 0.11200985 | D23: =C23*AD23 -> 0.11200985 | F23: 980 | G23: INR | H23: 1000 | J23: 50 | L23: 26.787982 | M23: 0.1003 | N23: 45175 | O23: 45906 | P23: =ROUND(YEARFRAC(N23,O23),0) -> 2 | Q23: =(M23*H23)/F23 -> 0.10234694 | R23: =IF(S23="Quarterly",4,IF(S23="Semi-annual",2,IF(S23="Annual",1,IF(S23="Pays at maturity",0,IF(S23="Monthly",12,0))))) -> 1 | S23: Annual | U23: =R23*P23 -> 2 | V23: =(H23*M23)/AD23 -> 100.3 | W23: =RATE(U23,V23,-F23,H23) -> 0.11200985 | X23: =W23*AD23 -> 0.11200985 | Y23: =DURATION(N23,O23,M23,D23,AD23) -> 1.9079622 | Z23: =Y23/(1+C23) -> 1.7157781 | AA23: =-Z23*F23 -> -1681.4626 | AB23: None | AC23: India | AD23: =_xlfn.SWITCH(PROPER(TRIM(S23)), "Annual",1, "Semi-Annual",2, "Quarterly",4, "Monthly",12, "") -> 1
A24: 965VCL25 | B24: Vivriti Capital Pvt Ltd. | C24: =RATE(U24,V24,-F24,H24) -> 0.24775758 | D24: =C24*AD24 -> 0.99103031 | F24: 251 | G24: INR | H24: 1000 | J24: 1786 | M24: 0.0965 | N24: 45175 | O24: 45906 | P24: =ROUND(YEARFRAC(N24,O24),0) -> 2 | Q24: =(M24*H24)/F24 -> 0.38446215 | R24: =IF(S24="Quarterly",4,IF(S24="Semi-annual",2,IF(S24="Annual",1,IF(S24="Pays at maturity",0,IF(S24="Monthly",12,0))))) -> 4 | S24: Quarterly | U24: =R24*P24 -> 8 | V24: =(H24*M24)/AD24 -> 24.125 | W24: =RATE(U24,V24,-F24,H24) -> 0.24775758 | X24: =W24*AD24 -> 0.99103031 | Y24: =DURATION(N24,O24,M24,D24,AD24) -> 1.6294228 | Z24: =Y24/(1+C24) -> 1.3058809 | AA24: =-Z24*F24 -> -327.77611 | AB24: None | AC24: India | AD24: =_xlfn.SWITCH(PROPER(TRIM(S24)), "Annual",1, "Semi-Annual",2, "Quarterly",4, "Monthly",12, "") -> 4
A25: 910CAGL25 | B25: CreditAccess Grameen Ltd. | C25: =RATE(U25,V25,-F25,H25) -> 0.090118731 | D25: =C25*AD25 -> 0.090118731 | F25: 1001.55 | G25: INR | H25: 1000 | J25: 25 | L25: 8.4053452 | M25: 0.091 | N25: 45176 | O25: 45907 | P25: =ROUND(YEARFRAC(N25,O25),0) -> 2 | Q25: =(M25*H25)/F25 -> 0.090859168 | R25: =IF(S25="Quarterly",4,IF(S25="Semi-annual",2,IF(S25="Annual",1,IF(S25="Pays at maturity",0,IF(S25="Monthly",12,0))))) -> 1 | S25: Annual | U25: =R25*P25 -> 2 | V25: =(H25*M25)/AD25 -> 91 | W25: =RATE(U25,V25,-F25,H25) -> 0.090118731 | X25: =W25*AD25 -> 0.090118731 | Y25: =DURATION(N25,O25,M25,D25,AD25) -> 1.916652 | Z25: =Y25/(1+C25) -> 1.7582049 | AA25: =-Z25*F25 -> -1760.9301 | AB25: None | AC25: India | AD25: =_xlfn.SWITCH(PROPER(TRIM(S25)), "Annual",1, "Semi-Annual",2, "Quarterly",4, "Monthly",12, "") -> 1
A27: 1050CCI25 | B27: Chemmanur Credits & Investments Ltd. | C27: =RATE(U27,V27,-F27,H27) -> 0.11055276 | D27: =C27*AD27 -> 0.11055276 | F27: 995 | G27: INR | H27: 1000 | J27: 10 | L27: 13.418656 | M27: 0.105 | N27: 45362 | O27: 45910 | P27: =ROUND(YEARFRAC(N27,O27),0) -> 1 | Q27: =(M27*H27)/F27 -> 0.10552764 | R27: =IF(S27="Quarterly",4,IF(S27="Semi-annual",2,IF(S27="Annual",1,IF(S27="Pays at maturity",0,IF(S27="Monthly",12,0))))) -> 1 | S27: Annual | U27: =R27*P27 -> 1 | V27: =(H27*M27)/AD27 -> 105 | W27: =RATE(U27,V27,-F27,H27) -> 0.11055276 | X27: =W27*AD27 -> 0.11055276 | Y27: =DURATION(N27,O27,M27,D27,AD27) -> 1.4017677 | Z27: =Y27/(1+C27) -> 1.2622252 | AA27: =-Z27*F27 -> -1255.9141 | AB27: None | AC27: India | AD27: =_xlfn.SWITCH(PROPER(TRIM(S27)), "Annual",1, "Semi-Annual",2, "Quarterly",4, "Monthly",12, "") -> 1
A28: 950KLM25 | B28: KLM Axiva Finvest Ltd. | C28: =RATE(U28,V28,-F28,H28) -> 0.10076784 | D28: =C28*AD28 -> 0.10076784 | F28: 990 | G28: INR | H28: 1000 | J28: 10 | L28: 12.476326 | M28: 0.095 | N28: 45181 | O28: 45911 | P28: =ROUND(YEARFRAC(N28,O28),0) -> 2 | Q28: =(M28*H28)/F28 -> 0.095959596 | R28: =IF(S28="Quarterly",4,IF(S28="Semi-annual",2,IF(S28="Annual",1,IF(S28="Pays at maturity",0,IF(S28="Monthly",12,0))))) -> 1 | S28: Annual | U28: =R28*P28 -> 2 | V28: =(H28*M28)/AD28 -> 95 | W28: =RATE(U28,V28,-F28,H28) -> 0.10076784 | X28: =W28*AD28 -> 0.10076784 | Y28: =DURATION(N28,O28,M28,D28,AD28) -> 1.9100471 | Z28: =Y28/(1+C28) -> 1.7351952 | AA28: =-Z28*F28 -> -1717.8432 | AB28: None | AC28: India | AD28: =_xlfn.SWITCH(PROPER(TRIM(S28)), "Annual",1, "Semi-Annual",2, "Quarterly",4, "Monthly",12, "") -> 1
A29: 95KAFL25 | B29: KLM Axiva Finvest Ltd. | C29: =RATE(U29,V29,-F29,H29) -> 0.11620795 | D29: =C29*AD29 -> 0.11620795 | F29: 981 | G29: INR | H29: 1000 | J29: 10 | L29: 22.086306 | M29: 0.095 | N29: 45512 | O29: 45911 | P29: =ROUND(YEARFRAC(N29,O29),0) -> 1 | Q29: =(M29*H29)/F29 -> 0.096839959 | R29: =IF(S29="Quarterly",4,IF(S29="Semi-annual",2,IF(S29="Annual",1,IF(S29="Pays at maturity",0,IF(S29="Monthly",12,0))))) -> 1 | S29: Annual | U29: =R29*P29 -> 1 | V29: =(H29*M29)/AD29 -> 95 | W29: =RATE(U29,V29,-F29,H29) -> 0.11620795 | X29: =W29*AD29 -> 0.11620795 | Y29: =DURATION(N29,O29,M29,D29,AD29) -> 1.0033767 | Z29: =Y29/(1+C29) -> 0.89891557 | AA29: =-Z29*F29 -> -881.83617 | AB29: None | AC29: India | AD29: =_xlfn.SWITCH(PROPER(TRIM(S29)), "Annual",1, "Semi-Annual",2, "Quarterly",4, "Monthly",12, "") -> 1
A30: 10NFL25 | B30: Navi Finserv Ltd. | C30: =RATE(U30,V30,-F30,H30) -> 0.10173259 | D30: =C30*AD30 -> 0.10173259 | F30: 997 | G30: INR | H30: 1000 | J30: 20 | L30: 12.102345 | M30: 0.1 | N30: 45364 | O30: 45913 | P30: =ROUND(YEARFRAC(N30,O30),0) -> 2 | Q30: =(M30*H30)/F30 -> 0.1003009 | R30: =IF(S30="Quarterly",4,IF(S30="Semi-annual",2,IF(S30="Annual",1,IF(S30="Pays at maturity",0,IF(S30="Monthly",12,0))))) -> 1 | S30: Annual | U30: =R30*P30 -> 2 | V30: =(H30*M30)/AD30 -> 100 | W30: =RATE(U30,V30,-F30,H30) -> 0.10173259 | X30: =W30*AD30 -> 0.10173259 | Y30: =DURATION(N30,O30,M30,D30,AD30) -> 1.4089608 | Z30: =Y30/(1+C30) -> 1.2788591 | AA30: =-Z30*F30 -> -1275.0225 | AB30: None | AC30: India | AD30: =_xlfn.SWITCH(PROPER(TRIM(S30)), "Annual",1, "Semi-Annual",2, "Quarterly",4, "Monthly",12, "") -> 1
A31: 895NHFL25 | B31: Nido Home Finance Ltd. | C31: =RATE(U31,V31,-F31,H31) -> 0.056474072 | D31: =C31*AD31 -> 0.056474072 | F31: 1060.85 | G31: INR | H31: 1000 | J31: 14 | L31: -29.629328 | M31: 0.0895 | N31: 45184 | O31: 45915 | P31: =ROUND(YEARFRAC(N31,O31),0) -> 2 | Q31: =(M31*H31)/F31 -> 0.08436631 | R31: =IF(S31="Quarterly",4,IF(S31="Semi-annual",2,IF(S31="Annual",1,IF(S31="Pays at maturity",0,IF(S31="Monthly",12,0))))) -> 1 | S31: Annual | U31: =R31*P31 -> 2 | V31: =(H31*M31)/AD31 -> 89.5 | W31: =RATE(U31,V31,-F31,H31) -> 0.056474072 | X31: =W31*AD31 -> 0.056474072 | Y31: =DURATION(N31,O31,M31,D31,AD31) -> 1.9201435 | Z31: =Y31/(1+C31) -> 1.8175018 | AA31: =-Z31*F31 -> -1928.0968 | AB31: None | AC31: India | AD31: =_xlfn.SWITCH(PROPER(TRIM(S31)), "Annual",1, "Semi-Annual",2, "Quarterly",4, "Monthly",12, "") -> 1
A32: 1025NFL25A | B32: Navi Finserv Ltd. | C32: =RATE(U32,V32,-F32,H32) -> 0.025260973 | D32: =C32*AD32 -> 0.10104389 | F32: 100136.86 | G32: INR | H32: 100000 | J32: 1 | M32: 0.1025 | N32: 45447 | O32: 45915 | P32: =ROUND(YEARFRAC(N32,O32),0) -> 1 | Q32: =(M32*H32)/F32 -> 0.10235991 | R32: =IF(S32="Quarterly",4,IF(S32="Semi-annual",2,IF(S32="Annual",1,IF(S32="Pays at maturity",0,IF(S32="Monthly",12,0))))) -> 4 | S32: Quarterly | U32: =R32*P32 -> 4 | V32: =(H32*M32)/AD32 -> 2562.5 | W32: =RATE(U32,V32,-F32,H32) -> 0.025260973 | X32: =W32*AD32 -> 0.10104389 | Y32: =DURATION(N32,O32,M32,D32,AD32) -> 1.1900335 | Z32: =Y32/(1+C32) -> 1.1607127 | AA32: =-Z32*F32 -> -116230.13 | AB32: None | AC32: India | AD32: =_xlfn.SWITCH(PROPER(TRIM(S32)), "Annual",1, "Semi-Annual",2, "Quarterly",4, "Monthly",12, "") -> 4
A34: 11IML25 | B34: Indel Money Pvt Ltd. | C34: =RATE(U34,V34,-F34,H34) -> 0.11949556 | D34: =C34*AD34 -> 0.11949556 | F34: 99151.8 | G34: INR | H34: 100000 | J34: 1 | L34: 13.108561 | M34: 0.11 | N34: 45462 | O34: 45919 | P34: =ROUND(YEARFRAC(N34,O34),0) -> 1 | Q34: =(M34*H34)/F34 -> 0.110941 | R34: =IF(S34="Quarterly",4,IF(S34="Semi-annual",2,IF(S34="Annual",1,IF(S34="Pays at maturity",0,IF(S34="Monthly",12,0))))) -> 1 | S34: Annual | U34: =R34*P34 -> 1 | V34: =(H34*M34)/AD34 -> 11000 | W34: =RATE(U34,V34,-F34,H34) -> 0.11949556 | X34: =W34*AD34 -> 0.11949556 | Y34: =DURATION(N34,O34,M34,D34,AD34) -> 1.1501378 | Z34: =Y34/(1+C34) -> 1.0273715 | AA34: =-Z34*F34 -> -101865.73 | AB34: None | AC34: India | AD34: =_xlfn.SWITCH(PROPER(TRIM(S34)), "Annual",1, "Semi-Annual",2, "Quarterly",4, "Monthly",12, "") -> 1
A35: 9MFL25A | B35: Muthoot Fincorp Ltd. | C35: =RATE(U35,V35,-F35,H35) -> 0.050701231 | D35: =C35*AD35 -> 0.050701231 | F35: 1073 | G35: INR | H35: 1000 | J35: 1 | L35: -29.815757 | M35: 0.09 | N35: 45189 | O35: 45920 | P35: =ROUND(YEARFRAC(N35,O35),0) -> 2 | Q35: =(M35*H35)/F35 -> 0.08387698 | R35: =IF(S35="Quarterly",4,IF(S35="Semi-annual",2,IF(S35="Annual",1,IF(S35="Pays at maturity",0,IF(S35="Monthly",12,0))))) -> 1 | S35: Annual | U35: =R35*P35 -> 2 | V35: =(H35*M35)/AD35 -> 90 | W35: =RATE(U35,V35,-F35,H35) -> 0.050701231 | X35: =W35*AD35 -> 0.050701231 | Y35: =DURATION(N35,O35,M35,D35,AD35) -> 1.9201705 | Z35: =Y35/(1+C35) -> 1.8275133 | AA35: =-Z35*F35 -> -1960.9218 | AB35: None | AC35: India | AD35: =_xlfn.SWITCH(PROPER(TRIM(S35)), "Annual",1, "Semi-Annual",2, "Quarterly",4, "Monthly",12, "") -> 1
A36: 865MFL25A | B36: Muthoot Fincorp Ltd. | C36: =RATE(U36,V36,-F36,H36) -> 0.092086768 | D36: =C36*AD36 -> 0.092086768 | F36: 990.2 | G36: INR | H36: 1000 | J36: 21 | L36: 14.756278 | M36: 0.0865 | N36: 45189 | O36: 45920 | P36: =ROUND(YEARFRAC(N36,O36),0) -> 2 | Q36: =(M36*H36)/F36 -> 0.08735609 | R36: =IF(S36="Quarterly",4,IF(S36="Semi-annual",2,IF(S36="Annual",1,IF(S36="Pays at maturity",0,IF(S36="Monthly",12,0))))) -> 1 | S36: Annual | U36: =R36*P36 -> 2 | V36: =(H36*M36)/AD36 -> 86.5 | W36: =RATE(U36,V36,-F36,H36) -> 0.092086768 | X36: =W36*AD36 -> 0.092086768 | Y36: =DURATION(N36,O36,M36,D36,AD36) -> 1.9200099 | Z36: =Y36/(1+C36) -> 1.7581112 | AA36: =-Z36*F36 -> -1740.8817 | AB36: None | AC36: India | AD36: =_xlfn.SWITCH(PROPER(TRIM(S36)), "Annual",1, "Semi-Annual",2, "Quarterly",4, "Monthly",12, "") -> 1
A39: 1025KFL25 | B39: Kosamattam Finance Ltd. | C39: =RATE(U39,V39,-F39,H39) -> 0.10353902 | D39: =C39*AD39 -> 0.10353902 | F39: 995 | G39: INR | H39: 1000 | J39: 313 | L39: 11.200611 | M39: 0.1025 | N39: 43367 | O39: 45923 | P39: =ROUND(YEARFRAC(N39,O39),0) -> 7 | Q39: =(M39*H39)/F39 -> 0.10301508 | R39: =IF(S39="Quarterly",4,IF(S39="Semi-annual",2,IF(S39="Annual",1,IF(S39="Pays at maturity",0,IF(S39="Monthly",12,0))))) -> 1 | S39: Annual | U39: =R39*P39 -> 7 | V39: =(H39*M39)/AD39 -> 102.5 | W39: =RATE(U39,V39,-F39,H39) -> 0.10353902 | X39: =W39*AD39 -> 0.10353902 | Y39: =DURATION(N39,O39,M39,D39,AD39) -> 5.3162326 | Z39: =Y39/(1+C39) -> 4.8174396 | AA39: =-Z39*F39 -> -4793.3524 | AB39: None | AC39: India | AD39: =_xlfn.SWITCH(PROPER(TRIM(S39)), "Annual",1, "Semi-Annual",2, "Quarterly",4, "Monthly",12, "") -> 1
A42: 925SCL25 | B42: Sammaan Capital Ltd. | C42: =RATE(U42,V42,-F42,H42) -> 0.09857653 | D42: =C42*AD42 -> 0.09857653 | F42: 983 | G42: INR | H42: 1000 | J42: 200 | L42: 15.474703 | M42: 0.0888 | N42: 45195 | O42: 45926 | P42: =ROUND(YEARFRAC(N42,O42),0) -> 2 | Q42: =(M42*H42)/F42 -> 0.090335707 | R42: =IF(S42="Quarterly",4,IF(S42="Semi-annual",2,IF(S42="Annual",1,IF(S42="Pays at maturity",0,IF(S42="Monthly",12,0))))) -> 1 | S42: Annual | U42: =R42*P42 -> 2 | V42: =(H42*M42)/AD42 -> 88.8 | W42: =RATE(U42,V42,-F42,H42) -> 0.09857653 | X42: =W42*AD42 -> 0.09857653 | Y42: =DURATION(N42,O42,M42,D42,AD42) -> 1.9177702 | Z42: =Y42/(1+C42) -> 1.7456865 | AA42: =-Z42*F42 -> -1716.0098 | AB42: None | AC42: India | AD42: =_xlfn.SWITCH(PROPER(TRIM(S42)), "Annual",1, "Semi-Annual",2, "Quarterly",4, "Monthly",12, "") -> 1
A43: 965SCL25E | B43: Sammaan Capital Ltd. | C43: =RATE(U43,V43,-F43,H43) -> 0.056447068 | D43: =C43*AD43 -> 0.056447068 | F43: 1073.8 | G43: INR | H43: 1000 | J43: 325 | L43: -25.854442 | M43: 0.0965 | N43: 45195 | O43: 45926 | P43: =ROUND(YEARFRAC(N43,O43),0) -> 2 | Q43: =(M43*H43)/F43 -> 0.089867759 | R43: =IF(S43="Quarterly",4,IF(S43="Semi-annual",2,IF(S43="Annual",1,IF(S43="Pays at maturity",0,IF(S43="Monthly",12,0))))) -> 1 | S43: Annual | U43: =R43*P43 -> 2 | V43: =(H43*M43)/AD43 -> 96.5 | W43: =RATE(U43,V43,-F43,H43) -> 0.056447068 | X43: =W43*AD43 -> 0.056447068 | Y43: =DURATION(N43,O43,M43,D43,AD43) -> 1.914934 | Z43: =Y43/(1+C43) -> 1.8126171 | AA43: =-Z43*F43 -> -1946.3882 | AB43: None | AC43: India | AD43: =_xlfn.SWITCH(PROPER(TRIM(S43)), "Annual",1, "Semi-Annual",2, "Quarterly",4, "Monthly",12, "") -> 1
A44: 1050UCL25 | B44: Ugro Capital Ltd. | C44: =RATE(U44,V44,-F44,H44) -> 0.10699059 | D44: =C44*AD44 -> 0.10699059 | F44: 995.11 | G44: INR | H44: 1000 | J44: 30 | L44: 13.269205 | M44: 0.105 | N44: 44830 | O44: 45926 | P44: =ROUND(YEARFRAC(N44,O44),0) -> 3 | Q44: =(M44*H44)/F44 -> 0.10551597 | R44: =IF(S44="Quarterly",4,IF(S44="Semi-annual",2,IF(S44="Annual",1,IF(S44="Pays at maturity",0,IF(S44="Monthly",12,0))))) -> 1 | S44: Annual | U44: =R44*P44 -> 3 | V44: =(H44*M44)/AD44 -> 105 | W44: =RATE(U44,V44,-F44,H44) -> 0.10699059 | X44: =W44*AD44 -> 0.10699059 | Y44: =DURATION(N44,O44,M44,D44,AD44) -> 2.7232589 | Z44: =Y44/(1+C44) -> 2.460056 | AA44: =-Z44*F44 -> -2448.0264 | AB44: None | AC44: India | AD44: =_xlfn.SWITCH(PROPER(TRIM(S44)), "Annual",1, "Semi-Annual",2, "Quarterly",4, "Monthly",12, "") -> 1
A45: 1115LFL25 | B45: Lendingkart Finance Ltd. | C45: =RATE(U45,V45,-F45,H45) -> 0.089036518 | D45: =C45*AD45 -> 1.0684382 | F45: 22000 | G45: INR | H45: 100000 | J45: 1 | M45: 0.1115 | N45: 45196 | O45: 45927 | P45: =ROUND(YEARFRAC(N45,O45),0) -> 2 | Q45: =(M45*H45)/F45 -> 0.50681818 | R45: =IF(S45="Quarterly",4,IF(S45="Semi-annual",2,IF(S45="Annual",1,IF(S45="Pays at maturity",0,IF(S45="Monthly",12,0))))) -> 12 | S45: Monthly | U45: =R45*P45 -> 24 | V45: =(H45*M45)/AD45 -> 929.16667 | W45: =RATE(U45,V45,-F45,H45) -> 0.089036518 | X45: =W45*AD45 -> 1.0684382 | Y45: =DURATION(N45,O45,M45,D45,AD45) -> #NUM! | Z45: =Y45/(1+C45) -> #NUM! | AA45: =-Z45*F45 -> #NUM! | AB45: None | AC45: India | AD45: =_xlfn.SWITCH(PROPER(TRIM(S45)), "Annual",1, "Semi-Annual",2, "Quarterly",4, "Monthly",12, "") -> 12
A46: 875KFL2025 | B46: Kosamattam Finance Ltd. | C46: =RATE(U46,V46,-F46,H46) -> 0.093209447 | D46: =C46*AD46 -> 0.093209447 | F46: 990 | G46: INR | H46: 1000 | J46: 500 | L46: 12.252151 | M46: 0.0875 | N46: 45197 | O46: 45927 | P46: =ROUND(YEARFRAC(N46,O46),0) -> 2 | Q46: =(M46*H46)/F46 -> 0.088383838 | R46: =IF(S46="Quarterly",4,IF(S46="Semi-annual",2,IF(S46="Annual",1,IF(S46="Pays at maturity",0,IF(S46="Monthly",12,0))))) -> 1 | S46: Annual | U46: =R46*P46 -> 2 | V46: =(H46*M46)/AD46 -> 87.5 | W46: =RATE(U46,V46,-F46,H46) -> 0.093209447 | X46: =W46*AD46 -> 0.093209447 | Y46: =DURATION(N46,O46,M46,D46,AD46) -> 1.9163742 | Z46: =Y46/(1+C46) -> 1.7529799 | AA46: =-Z46*F46 -> -1735.4501 | AB46: None | AC46: India | AD46: =_xlfn.SWITCH(PROPER(TRIM(S46)), "Annual",1, "Semi-Annual",2, "Quarterly",4, "Monthly",12, "") -> 1
A47: 847SCL25 | B47: Sammaan Capital Ltd. | C47: =RATE(U47,V47,-F47,H47) -> 0.069327694 | D47: =C47*AD47 -> 0.069327694 | F47: 1062.2 | G47: INR | H47: 1000 | J47: 25 | L47: -22.220767 | M47: 0.093 | N47: 44832 | O47: 45928 | P47: =ROUND(YEARFRAC(N47,O47),0) -> 3 | Q47: =(M47*H47)/F47 -> 0.087554133 | R47: =IF(S47="Quarterly",4,IF(S47="Semi-annual",2,IF(S47="Annual",1,IF(S47="Pays at maturity",0,IF(S47="Monthly",12,0))))) -> 1 | S47: Annual | U47: =R47*P47 -> 3 | V47: =(H47*M47)/AD47 -> 93 | W47: =RATE(U47,V47,-F47,H47) -> 0.069327694 | X47: =W47*AD47 -> 0.069327694 | Y47: =DURATION(N47,O47,M47,D47,AD47) -> 2.7596752 | Z47: =Y47/(1+C47) -> 2.5807572 | AA47: =-Z47*F47 -> -2741.2803 | AB47: None | AC47: India | AD47: =_xlfn.SWITCH(PROPER(TRIM(S47)), "Annual",1, "Semi-Annual",2, "Quarterly",4, "Monthly",12, "") -> 1
A48: 955SCL27 | B48: Sammaan Capital Ltd. | C48: =RATE(U48,V48,-F48,H48) -> 0.091380134 | D48: =C48*AD48 -> 0.091380134 | F48: 995 | G48: INR | H48: 1000 | J48: 1 | L48: 11.682235 | M48: 0.0894 | N48: 44832 | O48: 45928 | P48: =ROUND(YEARFRAC(N48,O48),0) -> 3 | Q48: =(M48*H48)/F48 -> 0.089849246 | R48: =IF(S48="Quarterly",4,IF(S48="Semi-annual",2,IF(S48="Annual",1,IF(S48="Pays at maturity",0,IF(S48="Monthly",12,0))))) -> 1 | S48: Annual | U48: =R48*P48 -> 3 | V48: =(H48*M48)/AD48 -> 89.4 | W48: =RATE(U48,V48,-F48,H48) -> 0.091380134 | X48: =W48*AD48 -> 0.091380134 | Y48: =DURATION(N48,O48,M48,D48,AD48) -> 2.7599143 | Z48: =Y48/(1+C48) -> 2.5288295 | AA48: =-Z48*F48 -> -2516.1854 | AB48: None | AC48: India | AD48: =_xlfn.SWITCH(PROPER(TRIM(S48)), "Annual",1, "Semi-Annual",2, "Quarterly",4, "Monthly",12, "") -> 1
A50: 105MMFL25B | B50: Muthoottu Mini Financiers Ltd. | C50: =RATE(U50,V50,-F50,H50) -> 0.11039786 | D50: =C50*AD50 -> 0.11039786 | F50: 980.07 | G50: INR | H50: 1000 | J50: 10 | L50: 15.533246 | M50: 0.105 | N50: 44104 | O50: 45929 | P50: =ROUND(YEARFRAC(N50,O50),0) -> 5 | Q50: =(M50*H50)/F50 -> 0.1071352 | R50: =IF(S50="Quarterly",4,IF(S50="Semi-annual",2,IF(S50="Annual",1,IF(S50="Pays at maturity",0,IF(S50="Monthly",12,0))))) -> 1 | S50: Annual | U50: =R50*P50 -> 5 | V50: =(H50*M50)/AD50 -> 105 | W50: =RATE(U50,V50,-F50,H50) -> 0.11039786 | X50: =W50*AD50 -> 0.11039786 | Y50: =DURATION(N50,O50,M50,D50,AD50) -> 4.1236381 | Z50: =Y50/(1+C50) -> 3.7136582 | AA50: =-Z50*F50 -> -3639.645 | AB50: None | AC50: India | AD50: =_xlfn.SWITCH(PROPER(TRIM(S50)), "Annual",1, "Semi-Annual",2, "Quarterly",4, "Monthly",12, "") -> 1
A51: 875ARKA25 | B51: Arka Fincap Ltd. | C51: =RATE(U51,V51,-F51,H51) -> 0.14385314 | D51: =C51*AD51 -> 0.14385314 | F51: 870010 | G51: INR | H51: 1000000 | J51: 2 | L51: 27.099671 | M51: 0.0875 | N51: 44833 | O51: 45929 | P51: =ROUND(YEARFRAC(N51,O51),0) -> 3 | Q51: =(M51*H51)/F51 -> 0.10057356 | R51: =IF(S51="Quarterly",4,IF(S51="Semi-annual",2,IF(S51="Annual",1,IF(S51="Pays at maturity",0,IF(S51="Monthly",12,0))))) -> 1 | S51: Annual | U51: =R51*P51 -> 3 | V51: =(H51*M51)/AD51 -> 87500 | W51: =RATE(U51,V51,-F51,H51) -> 0.14385314 | X51: =W51*AD51 -> 0.14385314 | Y51: =DURATION(N51,O51,M51,D51,AD51) -> 2.7472819 | Z51: =Y51/(1+C51) -> 2.4017786 | AA51: =-Z51*F51 -> -2089571.4 | AB51: None | AC51: India | AD51: =_xlfn.SWITCH(PROPER(TRIM(S51)), "Annual",1, "Semi-Annual",2, "Quarterly",4, "Monthly",12, "") -> 1
A52: 775MFLTD25 | B52: Muthoot Finance Ltd. | C52: =RATE(U52,V52,-F52,H52) -> 0.046976397 | D52: =C52*AD52 -> 0.046976397 | F52: 1057 | G52: INR | H52: 1000 | J52: 68 | L52: -13.171121 | M52: 0.0775 | N52: 45203 | O52: 45934 | P52: =ROUND(YEARFRAC(N52,O52),0) -> 2 | Q52: =(M52*H52)/F52 -> 0.073320719 | R52: =IF(S52="Quarterly",4,IF(S52="Semi-annual",2,IF(S52="Annual",1,IF(S52="Pays at maturity",0,IF(S52="Monthly",12,0))))) -> 1 | S52: Annual | U52: =R52*P52 -> 2 | V52: =(H52*M52)/AD52 -> 77.5 | W52: =RATE(U52,V52,-F52,H52) -> 0.046976397 | X52: =W52*AD52 -> 0.046976397 | Y52: =DURATION(N52,O52,M52,D52,AD52) -> 1.9299691 | Z52: =Y52/(1+C52) -> 1.843374 | AA52: =-Z52*F52 -> -1948.4463 | AB52: None | AC52: India | AD52: =_xlfn.SWITCH(PROPER(TRIM(S52)), "Annual",1, "Semi-Annual",2, "Quarterly",4, "Monthly",12, "") -> 1
...

Sheet Steps in Analyzing a Bond
A1: Steps | B1: Description | C1: Sheets
A2: Step 1 | B2: IRR (Frequency based) | C2: Bond pricing from Base data
A3: Step 2 | B3: IRR (Annualised) | C3: Bond pricing from Base data, Base Data
A4: Step 3 | B4: Formation of Yield Cluster | C4: Base data
A5: Step 4 | B5: Average of yield cluster | C5: Cluster details, Base data
A6: Step 5 | B6: Effective Yield from cluster | C6: Bond pricing from Base data
A7: Step 6 | B7: Macaulay duration | C7: Bond pricing from Base data, DurationTemplate, Base Data
A8: Step 7 | B8: Modified duration | C8: Bond pricing from Base data, Duration Template, Base Data
A9: Step 8 | B9: Convexity Measure (in coupon frequency terms) | C9: Convexity Template
A10: Step 9 | B10: Convexity Measure (Years) | C10: Convexity Template
A11: Step 10 | B11: % Price change due to Duration and Convexity | C11: Convexity Template
A12: Step 11 | B12: Rich/Cheap Analysis | C12: Bond pricing from Base data

Sheet Base Data
A1: INPUTS | S1: CALCULATED FIELDS
A2: By MJK | X2: Step 2 | Y2: Step 3 | Z2: Step 6 | AA2: Step 7 | AB2: Step 4 | AD2: bps shock input --> | AE2: 100 | AF2: =AE2/10000 -> 0.01
A3: Symbol | B3: Issuer Name | C3: BOND TYPE | D3: Issue date | E3: Maturity date | F3: Face value | G3: Face value - Currency | H3: Ask Price | I3: Price - Currency | J3: Price % of face value | K3: Volume 1 day | L3: Current coupon % | M3: Coupon frequency | N3: Term to maturity | O3: Current yield % (Coupon/Current Ask Price) | P3: S&P rating | Q3: Yield to maturity % | R3: Exchange | S3: Term to Maturity (Years) | T3: Coupon Frequency2 | U3: Total No. of Coupons | V3: Coupon Amount | W3: IRR | X3: Yield (Annualised) | Y3: Yield Cluster | Z3: Macaulay Duration in Years | AA3: Modified Duration in Years | AB3: Average Cluster Yield | AC3: Calculated Bond Price | AD3: Rich/Cheap | AE3: P (+ shock) | AF3: P (-shock) | AG3: Convexity Estimation | AH3: Column4 | AI3: Coupon Yield | AJ3: Column5 | AK3: IRR2 | AL3: Yield (Annual) | AM3: Dollar Duration | AN3: Bond Type2 | AO3: Country | AP3: Yearly Payment Frequency
A4: 737NTPC35C | B4: NTPC Limited 7.37% 05-OCT-2035 | C4: Corporate | D4: 42282 | E4: 49587 | F4: 1000 | G4: INR | H4: 2088.8 | I4: INR | J4: 208.88 | K4: 20 | L4: 0.0737 | M4: Annual | N4: 3670 | O4: 3.5283416 | P4: BBB | R4: BSE | S4: =ROUND(YEARFRAC(D4,E4),0) -> 20 | T4: {=_xlfn.IFS(Table1[[#This Row],[Coupon frequency]]="Semi-annual",2,Table1[[#This Row],[Coupon frequency]]="Quarterly",4,Table1[[#This Row],[Coupon frequency]]="Annual",1,Table1[[#This Row],[Coupon frequency]]="Every 4 months",3,Table1[[#This Row],[Coupon frequency]]="Monthly",12)} -> 1 | U4: =Table1[[#This Row],[Term to Maturity (Years)]]*Table1[[#This Row],[Coupon Frequency2]] -> 20 | V4: =Table1[[#This Row],[Face value]]*Table1[[#This Row],[Current coupon %]] -> 73.7 | W4: =RATE(Table1[[#This Row],[Total No. of Coupons]],Table1[[#This Row],[Coupon Amount]],-Table1[[#This Row],[Ask Price]],Table1[[#This Row],[Face value]]) -> 0.012087753 | X4: =Table1[[#This Row],[IRR]]*Table1[[#This Row],[Coupon Frequency2]] -> 0.012087753 | Y4: {=_xlfn.IFS(Table1[[#This Row],[Yield (Annualised)]]<0.05,1,Table1[[#This Row],[Yield (Annualised)]]<0.1,2,Table1[[#This Row],[Yield (Annualised)]]<0.15,3,Table1[[#This Row],[Yield (Annualised)]]<0.2,4,Table1[[#This Row],[Yield (Annualised)]]<0.25,5,Table1[[#This Row],[Yield (Annualised)]]<0.3,6,Table1[[#This Row],[Yield (Annualised)]]<0.35,7,Table1[[#This Row],[Yield (Annualised)]]<0.4,8,Table1[[#This Row],[Yield (Annualised)]]<0.45,9,Table1[[#This Row],[Yield (Annualised)]]<0.5,10,Table1[[#This Row],[Yield (Annualised)]]<0.55,11,Table1[[#This Row],[Yield (Annualised)]]<0.6,12,Table1[[#This Row],[Yield (Annualised)]]<0.65,13,Table1[[#This Row],[Yield (Annualised)]]<0.7,14,Table1[[#This Row],[Yield (Annualised)]]>0.7,15)} -> 1 | Z4: =DURATION(Table1[[#This Row],[Issue date]],Table1[[#This Row],[Maturity date]],Table1[[#This Row],[Current coupon %]],Table1[[#This Row],[Yield (Annualised)]],Table1[[#This Row],[Coupon Frequency2]]) -> 13.82768 | AA4: =Table1[[#This Row],[Macaulay Duration in Years]]/(1+Table1[[#This Row],[IRR]]) -> 13.662531 | AB4: =VLOOKUP(Table1[[#This Row],[Yield Cluster]],'Cluster Details'!$B$3:$C$16,2,0) -> 0.034641747 | AC4: =PRICE(Table1[[#This Row],[Issue date]],Table1[[#This Row],[Maturity date]],Table1[[#This Row],[Current coupon %]],Table1[[#This Row],[Average Cluster Yield]],100,Table1[[#This Row],[Coupon Frequency2]])*Table1[[#This Row],[Face value]]/100 -> 1556.9154 | AD4: =IF(Table1[[#This Row],[Ask Price]]>Table1[[#This Row],[Calculated Bond Price]],"Rich","Cheap") -> Rich | AE4: =PRICE(Table1[[#This Row],[Issue date]],Table1[[#This Row],[Maturity date]],Table1[[#This Row],[Current coupon %]],Table1[[#This Row],[Yield (Annualised)]]+$AF$2,100,Table1[[#This Row],[Coupon Frequency2]])*Table1[[#This Row],[Face value]]/100 -> 1827.1753 | AF4: =PRICE(Table1[[#This Row],[Issue date]],Table1[[#This Row],[Maturity date]],Table1[[#This Row],[Current coupon %]],Table1[[#This Row],[Yield (Annualised)]]-$AF$2,100,Table1[[#This Row],[Coupon Frequency2]])*Table1[[#This Row],[Face value]]/100 -> 2401.3231 | AG4: =(Table1[[#This Row],[P (+ shock)]]+Table1[[#This Row],[P (-shock)]]-2*Table1[[#This Row],[Ask Price]])/(2*Table1[[#This Row],[Ask Price]]*($AF$2^2)) -> 121.83653 | AH4: 11.444721 | AI4: =(L4*F4)/H4 -> 0.035283416 | AK4: =RATE(Table1[[#This Row],[Total No. of Coupons]],Table1[[#This Row],[Coupon Amount]],-Table1[[#This Row],[Ask Price]],Table1[[#This Row],[Face value]]) -> 0.012087753 | AL4: =Table1[[#This Row],[IRR]]*Table1[[#This Row],[Coupon Frequency2]] -> 0.012087753 | AM4: =-AA4*H4 -> -28538.295 | AN4: None | AO4: India | AP4: =_xlfn.SWITCH(PROPER(TRIM(M4)), "Annual",1, "Semi-Annual",2, "Quarterly",4, "Monthly",12, "") -> 1
A5: 997MCSL25 | B5: Muthoot Capital Services Limited 9.97% 05-DEC-2025 | C5: Corporate | D5: 45601 | E5: 45996 | F5: 100000 | G5: INR | H5: 107624.42 | I5: INR | J5: 107.62442 | K5: 2 | L5: 0.0997 | M5: Annual | N5: 79 | O5: 9.2636968 | R5: BSE | S5: =ROUND(YEARFRAC(D5,E5),0) -> 1 | T5: {=_xlfn.IFS(Table1[[#This Row],[Coupon frequency]]="Semi-annual",2,Table1[[#This Row],[Coupon frequency]]="Quarterly",4,Table1[[#This Row],[Coupon frequency]]="Annual",1,Table1[[#This Row],[Coupon frequency]]="Every 4 months",3,Table1[[#This Row],[Coupon frequency]]="Monthly",12)} -> 1 | U5: =Table1[[#This Row],[Term to Maturity (Years)]]*Table1[[#This Row],[Coupon Frequency2]] -> 1 | V5: =Table1[[#This Row],[Face value]]*Table1[[#This Row],[Current coupon %]] -> 9970 | W5: =RATE(Table1[[#This Row],[Total No. of Coupons]],Table1[[#This Row],[Coupon Amount]],-Table1[[#This Row],[Ask Price]],Table1[[#This Row],[Face value]]) -> 0.021794124 | X5: =Table1[[#This Row],[IRR]]*Table1[[#This Row],[Coupon Frequency2]] -> 0.021794124 | Y5: {=_xlfn.IFS(Table1[[#This Row],[Yield (Annualised)]]<0.05,1,Table1[[#This Row],[Yield (Annualised)]]<0.1,2,Table1[[#This Row],[Yield (Annualised)]]<0.15,3,Table1[[#This Row],[Yield (Annualised)]]<0.2,4,Table1[[#This Row],[Yield (Annualised)]]<0.25,5,Table1[[#This Row],[Yield (Annualised)]]<0.3,6,Table1[[#This Row],[Yield (Annualised)]]<0.35,7,Table1[[#This Row],[Yield (Annualised)]]<0.4,8,Table1[[#This Row],[Yield (Annualised)]]<0.45,9,Table1[[#This Row],[Yield (Annualised)]]<0.5,10,Table1[[#This Row],[Yield (Annualised)]]<0.55,11,Table1[[#This Row],[Yield (Annualised)]]<0.6,12,Table1[[#This Row],[Yield (Annualised)]]<0.65,13,Table1[[#This Row],[Yield (Annualised)]]<0.7,14,Table1[[#This Row],[Yield (Annualised)]]>0.7,15)} -> 1 | Z5: =DURATION(Table1[[#This Row],[Issue date]],Table1[[#This Row],[Maturity date]],Table1[[#This Row],[Current coupon %]],Table1[[#This Row],[Yield (Annualised)]],Table1[[#This Row],[Coupon Frequency2]]) -> 0.9985504 | AA5: =Table1[[#This Row],[Macaulay Duration in Years]]/(1+Table1[[#This Row],[IRR]]) -> 0.97725205 | AB5: =VLOOKUP(Table1[[#This Row],[Yield Cluster]],'Cluster Details'!$B$3:$C$16,2,0) -> 0.034641747 | AC5: =PRICE(Table1[[#This Row],[Issue date]],Table1[[#This Row],[Maturity date]],Table1[[#This Row],[Current coupon %]],Table1[[#This Row],[Average Cluster Yield]],100,Table1[[#This Row],[Coupon Frequency2]])*Table1[[#This Row],[Face value]]/100 -> 106789.37 | AD5: =IF(Table1[[#This Row],[Ask Price]]>Table1[[#This Row],[Calculated Bond Price]],"Rich","Cheap") -> Rich | AE5: =PRICE(Table1[[#This Row],[Issue date]],Table1[[#This Row],[Maturity date]],Table1[[#This Row],[Current coupon %]],Table1[[#This Row],[Yield (Annualised)]]+$AF$2,100,Table1[[#This Row],[Coupon Frequency2]])*Table1[[#This Row],[Face value]]/100 -> 107108.57 | AF5: =PRICE(Table1[[#This Row],[Issue date]],Table1[[#This Row],[Maturity date]],Table1[[#This Row],[Current coupon %]],Table1[[#This Row],[Yield (Annualised)]]-$AF$2,100,Table1[[#This Row],[Coupon Frequency2]])*Table1[[#This Row],[Face value]]/100 -> 109403.07 | AG5: =(Table1[[#This Row],[P (+ shock)]]+Table1[[#This Row],[P (-shock)]]-2*Table1[[#This Row],[Ask Price]])/(2*Table1[[#This Row],[Ask Price]]*($AF$2^2)) -> 58.667042 | AH5: 9.5 | AI5: =(L5*F5)/H5 -> 0.092636968 | AK5: =RATE(Table1[[#This Row],[Total No. of Coupons]],Table1[[#This Row],[Coupon Amount]],-Table1[[#This Row],[Ask Price]],Table1[[#This Row],[Face value]]) -> 0.021794124 | AL5: =Table1[[#This Row],[IRR]]*Table1[[#This Row],[Coupon Frequency2]] -> 0.021794124 | AM5: =-AA5*H5 -> -105176.18 | AN5: None | AO5: India | AP5: =_xlfn.SWITCH(PROPER(TRIM(M5)), "Annual",1, "Semi-Annual",2, "Quarterly",4, "Monthly",12, "") -> 1
A6: 925IHFL25E | B6: Cholamandalam Investment and finance Company Limited 8.3% 09-SEP-2026 | C6: Corporate | D6: 45147 | E6: 46274 | F6: 1000 | G6: INR | H6: 1168.8 | I6: INR | J6: 116.88 | K6: 120 | L6: 0.083 | M6: Annual | N6: 357 | O6: 7.1013005 | R6: BSE | S6: =ROUND(YEARFRAC(D6,E6),0) -> 3 | T6: {=_xlfn.IFS(Table1[[#This Row],[Coupon frequency]]="Semi-annual",2,Table1[[#This Row],[Coupon frequency]]="Quarterly",4,Table1[[#This Row],[Coupon frequency]]="Annual",1,Table1[[#This Row],[Coupon frequency]]="Every 4 months",3,Table1[[#This Row],[Coupon frequency]]="Monthly",12)} -> 1 | U6: =Table1[[#This Row],[Term to Maturity (Years)]]*Table1[[#This Row],[Coupon Frequency2]] -> 3 | V6: =Table1[[#This Row],[Face value]]*Table1[[#This Row],[Current coupon %]] -> 83 | W6: =RATE(Table1[[#This Row],[Total No. of Coupons]],Table1[[#This Row],[Coupon Amount]],-Table1[[#This Row],[Ask Price]],Table1[[#This Row],[Face value]]) -> 0.024010037 | X6: =Table1[[#This Row],[IRR]]*Table1[[#This Row],[Coupon Frequency2]] -> 0.024010037 | Y6: {=_xlfn.IFS(Table1[[#This Row],[Yield (Annualised)]]<0.05,1,Table1[[#This Row],[Yield (Annualised)]]<0.1,2,Table1[[#This Row],[Yield (Annualised)]]<0.15,3,Table1[[#This Row],[Yield (Annualised)]]<0.2,4,Table1[[#This Row],[Yield (Annualised)]]<0.25,5,Table1[[#This Row],[Yield (Annualised)]]<0.3,6,Table1[[#This Row],[Yield (Annualised)]]<0.35,7,Table1[[#This Row],[Yield (Annualised)]]<0.4,8,Table1[[#This Row],[Yield (Annualised)]]<0.45,9,Table1[[#This Row],[Yield (Annualised)]]<0.5,10,Table1[[#This Row],[Yield (Annualised)]]<0.55,11,Table1[[#This Row],[Yield (Annualised)]]<0.6,12,Table1[[#This Row],[Yield (Annualised)]]<0.65,13,Table1[[#This Row],[Yield (Annualised)]]<0.7,14,Table1[[#This Row],[Yield (Annualised)]]>0.7,15)} -> 1 | Z6: =DURATION(Table1[[#This Row],[Issue date]],Table1[[#This Row],[Maturity date]],Table1[[#This Row],[Current coupon %]],Table1[[#This Row],[Yield (Annualised)]],Table1[[#This Row],[Coupon Frequency2]]) -> 2.6916883 | AA6: =Table1[[#This Row],[Macaulay Duration in Years]]/(1+Table1[[#This Row],[IRR]]) -> 2.6285761 | AB6: =VLOOKUP(Table1[[#This Row],[Yield Cluster]],'Cluster Details'!$B$3:$C$16,2,0) -> 0.034641747 | AC6: =PRICE(Table1[[#This Row],[Issue date]],Table1[[#This Row],[Maturity date]],Table1[[#This Row],[Current coupon %]],Table1[[#This Row],[Average Cluster Yield]],100,Table1[[#This Row],[Coupon Frequency2]])*Table1[[#This Row],[Face value]]/100 -> 1139.0384 | AD6: =IF(Table1[[#This Row],[Ask Price]]>Table1[[#This Row],[Calculated Bond Price]],"Rich","Cheap") -> Rich | AE6: =PRICE(Table1[[#This Row],[Issue date]],Table1[[#This Row],[Maturity date]],Table1[[#This Row],[Current coupon %]],Table1[[#This Row],[Yield (Annualised)]]+$AF$2,100,Table1[[#This Row],[Coupon Frequency2]])*Table1[[#This Row],[Face value]]/100 -> 1141.0318 | AF6: =PRICE(Table1[[#This Row],[Issue date]],Table1[[#This Row],[Maturity date]],Table1[[#This Row],[Current coupon %]],Table1[[#This Row],[Yield (Annualised)]]-$AF$2,100,Table1[[#This Row],[Coupon Frequency2]])*Table1[[#This Row],[Face value]]/100 -> 1206.7317 | AG6: =(Table1[[#This Row],[P (+ shock)]]+Table1[[#This Row],[P (-shock)]]-2*Table1[[#This Row],[Ask Price]])/(2*Table1[[#This Row],[Ask Price]]*($AF$2^2)) -> 43.478563 | AI6: =(L6*F6)/H6 -> 0.071013005 | AK6: =RATE(Table1[[#This Row],[Total No. of Coupons]],Table1[[#This Row],[Coupon Amount]],-Table1[[#This Row],[Ask Price]],Table1[[#This Row],[Face value]]) -> 0.024010037 | AL6: =Table1[[#This Row],[IRR]]*Table1[[#This Row],[Coupon Frequency2]] -> 0.024010037 | AM6: =-AA6*H6 -> -3072.2798 | AN6: None | AO6: India | AP6: =_xlfn.SWITCH(PROPER(TRIM(M6)), "Annual",1, "Semi-Annual",2, "Quarterly",4, "Monthly",12, "") -> 1
A7: 99SCL27V | B7: Sammaan Capital Limited 9.9% 27-DEC-2027 | C7: Corporate | D7: 45653 | E7: 46748 | F7: 1000 | G7: INR | H7: 1199 | I7: INR | J7: 119.9 | K7: 401 | L7: 0.099 | M7: Annual | N7: 831 | O7: 8.2568807 | P7: B+ | R7: BSE | S7: =ROUND(YEARFRAC(D7,E7),0) -> 3 | T7: {=_xlfn.IFS(Table1[[#This Row],[Coupon frequency]]="Semi-annual",2,Table1[[#This Row],[Coupon frequency]]="Quarterly",4,Table1[[#This Row],[Coupon frequency]]="Annual",1,Table1[[#This Row],[Coupon frequency]]="Every 4 months",3,Table1[[#This Row],[Coupon frequency]]="Monthly",12)} -> 1 | U7: =Table1[[#This Row],[Term to Maturity (Years)]]*Table1[[#This Row],[Coupon Frequency2]] -> 3 | V7: =Table1[[#This Row],[Face value]]*Table1[[#This Row],[Current coupon %]] -> 99 | W7: =RATE(Table1[[#This Row],[Total No. of Coupons]],Table1[[#This Row],[Coupon Amount]],-Table1[[#This Row],[Ask Price]],Table1[[#This Row],[Face value]]) -> 0.028808554 | X7: =Table1[[#This Row],[IRR]]*Table1[[#This Row],[Coupon Frequency2]] -> 0.028808554 | Y7: {=_xlfn.IFS(Table1[[#This Row],[Yield (Annualised)]]<0.05,1,Table1[[#This Row],[Yield (Annualised)]]<0.1,2,Table1[[#This Row],[Yield (Annualised)]]<0.15,3,Table1[[#This Row],[Yield (Annualised)]]<0.2,4,Table1[[#This Row],[Yield (Annualised)]]<0.25,5,Table1[[#This Row],[Yield (Annualised)]]<0.3,6,Table1[[#This Row],[Yield (Annualised)]]<0.35,7,Table1[[#This Row],[Yield (Annualised)]]<0.4,8,Table1[[#This Row],[Yield (Annualised)]]<0.45,9,Table1[[#This Row],[Yield (Annualised)]]<0.5,10,Table1[[#This Row],[Yield (Annualised)]]<0.55,11,Table1[[#This Row],[Yield (Annualised)]]<0.6,12,Table1[[#This Row],[Yield (Annualised)]]<0.65,13,Table1[[#This Row],[Yield (Annualised)]]<0.7,14,Table1[[#This Row],[Yield (Annualised)]]>0.7,15)} -> 1 | Z7: =DURATION(Table1[[#This Row],[Issue date]],Table1[[#This Row],[Maturity date]],Table1[[#This Row],[Current coupon %]],Table1[[#This Row],[Yield (Annualised)]],Table1[[#This Row],[Coupon Frequency2]]) -> 2.7614772 | AA7: =Table1[[#This Row],[Macaulay Duration in Years]]/(1+Table1[[#This Row],[IRR]]) -> 2.6841507 | AB7: =VLOOKUP(Table1[[#This Row],[Yield Cluster]],'Cluster Details'!$B$3:$C$16,2,0) -> 0.034641747 | AC7: =PRICE(Table1[[#This Row],[Issue date]],Table1[[#This Row],[Maturity date]],Table1[[#This Row],[Current coupon %]],Table1[[#This Row],[Average Cluster Yield]],100,Table1[[#This Row],[Coupon Frequency2]])*Table1[[#This Row],[Face value]]/100 -> 1180.4319 | AD7: =IF(Table1[[#This Row],[Ask Price]]>Table1[[#This Row],[Calculated Bond Price]],"Rich","Cheap") -> Rich | AE7: =PRICE(Table1[[#This Row],[Issue date]],Table1[[#This Row],[Maturity date]],Table1[[#This Row],[Current coupon %]],Table1[[#This Row],[Yield (Annualised)]]+$AF$2,100,Table1[[#This Row],[Coupon Frequency2]])*Table1[[#This Row],[Face value]]/100 -> 1167.4152 | AF7: =PRICE(Table1[[#This Row],[Issue date]],Table1[[#This Row],[Maturity date]],Table1[[#This Row],[Current coupon %]],Table1[[#This Row],[Yield (Annualised)]]-$AF$2,100,Table1[[#This Row],[Coupon Frequency2]])*Table1[[#This Row],[Face value]]/100 -> 1231.8005 | AG7: =(Table1[[#This Row],[P (+ shock)]]+Table1[[#This Row],[P (-shock)]]-2*Table1[[#This Row],[Ask Price]])/(2*Table1[[#This Row],[Ask Price]]*($AF$2^2)) -> 5.0696214 | AI7: =(L7*F7)/H7 -> 0.082568807 | AK7: =RATE(Table1[[#This Row],[Total No. of Coupons]],Table1[[#This Row],[Coupon Amount]],-Table1[[#This Row],[Ask Price]],Table1[[#This Row],[Face value]]) -> 0.028808554 | AL7: =Table1[[#This Row],[IRR]]*Table1[[#This Row],[Coupon Frequency2]] -> 0.028808554 | AM7: =-AA7*H7 -> -3218.2966 | AN7: Callable | AO7: India | AP7: =_xlfn.SWITCH(PROPER(TRIM(M7)), "Annual",1, "Semi-Annual",2, "Quarterly",4, "Monthly",12, "") -> 1
A8: 725IRFC35 | B8: Indian Railway Finance Corporation Limited 7.25% 21-DEC-2035 | C8: Corporate | D8: 42359 | E8: 49664 | F8: 1000 | G8: INR | H8: 1475 | I8: INR | J8: 147.5 | K8: 5 | L8: 0.0725 | M8: Annual | N8: 3747 | O8: 4.9152542 | P8: BBB | R8: BSE | S8: =ROUND(YEARFRAC(D8,E8),0) -> 20 | T8: {=_xlfn.IFS(Table1[[#This Row],[Coupon frequency]]="Semi-annual",2,Table1[[#This Row],[Coupon frequency]]="Quarterly",4,Table1[[#This Row],[Coupon frequency]]="Annual",1,Table1[[#This Row],[Coupon frequency]]="Every 4 months",3,Table1[[#This Row],[Coupon frequency]]="Monthly",12)} -> 1 | U8: =Table1[[#This Row],[Term to Maturity (Years)]]*Table1[[#This Row],[Coupon Frequency2]] -> 20 | V8: =Table1[[#This Row],[Face value]]*Table1[[#This Row],[Current coupon %]] -> 72.5 | W8: =RATE(Table1[[#This Row],[Total No. of Coupons]],Table1[[#This Row],[Coupon Amount]],-Table1[[#This Row],[Ask Price]],Table1[[#This Row],[Face value]]) -> 0.038126145 | X8: =Table1[[#This Row],[IRR]]*Table1[[#This Row],[Coupon Frequency2]] -> 0.038126145 | Y8: {=_xlfn.IFS(Table1[[#This Row],[Yield (Annualised)]]<0.05,1,Table1[[#This Row],[Yield (Annualised)]]<0.1,2,Table1[[#This Row],[Yield (Annualised)]]<0.15,3,Table1[[#This Row],[Yield (Annualised)]]<0.2,4,Table1[[#This Row],[Yield (Annualised)]]<0.25,5,Table1[[#This Row],[Yield (Annualised)]]<0.3,6,Table1[[#This Row],[Yield (Annualised)]]<0.35,7,Table1[[#This Row],[Yield (Annualised)]]<0.4,8,Table1[[#This Row],[Yield (Annualised)]]<0.45,9,Table1[[#This Row],[Yield (Annualised)]]<0.5,10,Table1[[#This Row],[Yield (Annualised)]]<0.55,11,Table1[[#This Row],[Yield (Annualised)]]<0.6,12,Table1[[#This Row],[Yield (Annualised)]]<0.65,13,Table1[[#This Row],[Yield (Annualised)]]<0.7,14,Table1[[#This Row],[Yield (Annualised)]]>0.7,15)} -> 1 | Z8: =DURATION(Table1[[#This Row],[Issue date]],Table1[[#This Row],[Maturity date]],Table1[[#This Row],[Current coupon %]],Table1[[#This Row],[Yield (Annualised)]],Table1[[#This Row],[Coupon Frequency2]]) -> 12.710163 | AA8: =Table1[[#This Row],[Macaulay Duration in Years]]/(1+Table1[[#This Row],[IRR]]) -> 12.243371 | AB8: =VLOOKUP(Table1[[#This Row],[Yield Cluster]],'Cluster Details'!$B$3:$C$16,2,0) -> 0.034641747 | AC8: =PRICE(Table1[[#This Row],[Issue date]],Table1[[#This Row],[Maturity date]],Table1[[#This Row],[Current coupon %]],Table1[[#This Row],[Average Cluster Yield]],100,Table1[[#This Row],[Coupon Frequency2]])*Table1[[#This Row],[Face value]]/100 -> 1539.8051 | AD8: =IF(Table1[[#This Row],[Ask Price]]>Table1[[#This Row],[Calculated Bond Price]],"Rich","Cheap") -> Cheap | AE8: =PRICE(Table1[[#This Row],[Issue date]],Table1[[#This Row],[Maturity date]],Table1[[#This Row],[Current coupon %]],Table1[[#This Row],[Yield (Annualised)]]+$AF$2,100,Table1[[#This Row],[Coupon Frequency2]])*Table1[[#This Row],[Face value]]/100 -> 1308.6368 | AF8: =PRICE(Table1[[#This Row],[Issue date]],Table1[[#This Row],[Maturity date]],Table1[[#This Row],[Current coupon %]],Table1[[#This Row],[Yield (Annualised)]]-$AF$2,100,Table1[[#This Row],[Coupon Frequency2]])*Table1[[#This Row],[Face value]]/100 -> 1671.7549 | AG8: =(Table1[[#This Row],[P (+ shock)]]+Table1[[#This Row],[P (-shock)]]-2*Table1[[#This Row],[Ask Price]])/(2*Table1[[#This Row],[Ask Price]]*($AF$2^2)) -> 103.02263 | AH8: 3.4759956 | AI8: =(L8*F8)/H8 -> 0.049152542 | AK8: =RATE(Table1[[#This Row],[Total No. of Coupons]],Table1[[#This Row],[Coupon Amount]],-Table1[[#This Row],[Ask Price]],Table1[[#This Row],[Face value]]) -> 0.038126145 | AL8: =Table1[[#This Row],[IRR]]*Table1[[#This Row],[Coupon Frequency2]] -> 0.038126145 | AM8: =-AA8*H8 -> -18058.972 | AN8: None | AO8: India | AP8: =_xlfn.SWITCH(PROPER(TRIM(M8)), "Annual",1, "Semi-Annual",2, "Quarterly",4, "Monthly",12, "") -> 1
A9: 711PFCL25 | B9: Power Finance Corporation Limited 7.11% 17-OCT-2025 | C9: Corporate | D9: 42294 | E9: 45947 | F9: 1000 | G9: INR | H9: 1235.8 | I9: INR | J9: 123.58 | K9: 8 | L9: 0.0711 | M9: Annual | N9: 30 | O9: 5.7533581 | P9: NR | R9: BSE | S9: =ROUND(YEARFRAC(D9,E9),0) -> 10 | T9: {=_xlfn.IFS(Table1[[#This Row],[Coupon frequency]]="Semi-annual",2,Table1[[#This Row],[Coupon frequency]]="Quarterly",4,Table1[[#This Row],[Coupon frequency]]="Annual",1,Table1[[#This Row],[Coupon frequency]]="Every 4 months",3,Table1[[#This Row],[Coupon frequency]]="Monthly",12)} -> 1 | U9: =Table1[[#This Row],[Term to Maturity (Years)]]*Table1[[#This Row],[Coupon Frequency2]] -> 10 | V9: =Table1[[#This Row],[Face value]]*Table1[[#This Row],[Current coupon %]] -> 71.1 | W9: =RATE(Table1[[#This Row],[Total No. of Coupons]],Table1[[#This Row],[Coupon Amount]],-Table1[[#This Row],[Ask Price]],Table1[[#This Row],[Face value]]) -> 0.041771107 | X9: =Table1[[#This Row],[IRR]]*Table1[[#This Row],[Coupon Frequency2]] -> 0.041771107 | Y9: {=_xlfn.IFS(Table1[[#This Row],[Yield (Annualised)]]<0.05,1,Table1[[#This Row],[Yield (Annualised)]]<0.1,2,Table1[[#This Row],[Yield (Annualised)]]<0.15,3,Table1[[#This Row],[Yield (Annualised)]]<0.2,4,Table1[[#This Row],[Yield (Annualised)]]<0.25,5,Table1[[#This Row],[Yield (Annualised)]]<0.3,6,Table1[[#This Row],[Yield (Annualised)]]<0.35,7,Table1[[#This Row],[Yield (Annualised)]]<0.4,8,Table1[[#This Row],[Yield (Annualised)]]<0.45,9,Table1[[#This Row],[Yield (Annualised)]]<0.5,10,Table1[[#This Row],[Yield (Annualised)]]<0.55,11,Table1[[#This Row],[Yield (Annualised)]]<0.6,12,Table1[[#This Row],[Yield (Annualised)]]<0.65,13,Table1[[#This Row],[Yield (Annualised)]]<0.7,14,Table1[[#This Row],[Yield (Annualised)]]>0.7,15)} -> 1 | Z9: =DURATION(Table1[[#This Row],[Issue date]],Table1[[#This Row],[Maturity date]],Table1[[#This Row],[Current coupon %]],Table1[[#This Row],[Yield (Annualised)]],Table1[[#This Row],[Coupon Frequency2]]) -> 7.7627467 | AA9: =Table1[[#This Row],[Macaulay Duration in Years]]/(1+Table1[[#This Row],[IRR]]) -> 7.4514897 | AB9: =VLOOKUP(Table1[[#This Row],[Yield Cluster]],'Cluster Details'!$B$3:$C$16,2,0) -> 0.034641747 | AC9: =PRICE(Table1[[#This Row],[Issue date]],Table1[[#This Row],[Maturity date]],Table1[[#This Row],[Current coupon %]],Table1[[#This Row],[Average Cluster Yield]],100,Table1[[#This Row],[Coupon Frequency2]])*Table1[[#This Row],[Face value]]/100 -> 1303.7571 | AD9: =IF(Table1[[#This Row],[Ask Price]]>Table1[[#This Row],[Calculated Bond Price]],"Rich","Cheap") -> Cheap | AE9: =PRICE(Table1[[#This Row],[Issue date]],Table1[[#This Row],[Maturity date]],Table1[[#This Row],[Current coupon %]],Table1[[#This Row],[Yield (Annualised)]]+$AF$2,100,Table1[[#This Row],[Coupon Frequency2]])*Table1[[#This Row],[Face value]]/100 -> 1147.9772 | AF9: =PRICE(Table1[[#This Row],[Issue date]],Table1[[#This Row],[Maturity date]],Table1[[#This Row],[Current coupon %]],Table1[[#This Row],[Yield (Annualised)]]-$AF$2,100,Table1[[#This Row],[Coupon Frequency2]])*Table1[[#This Row],[Face value]]/100 -> 1332.4714 | AG9: =(Table1[[#This Row],[P (+ shock)]]+Table1[[#This Row],[P (-shock)]]-2*Table1[[#This Row],[Ask Price]])/(2*Table1[[#This Row],[Ask Price]]*($AF$2^2)) -> 35.800889 | AH9: 0.8432257 | AI9: =(L9*F9)/H9 -> 0.057533581 | AK9: =RATE(Table1[[#This Row],[Total No. of Coupons]],Table1[[#This Row],[Coupon Amount]],-Table1[[#This Row],[Ask Price]],Table1[[#This Row],[Face value]]) -> 0.041771107 | AL9: =Table1[[#This Row],[IRR]]*Table1[[#This Row],[Coupon Frequency2]] -> 0.041771107 | AM9: =-AA9*H9 -> -9208.551 | AN9: None | AO9: India | AP9: =_xlfn.SWITCH(PROPER(TRIM(M9)), "Annual",1, "Semi-Annual",2, "Quarterly",4, "Monthly",12, "") -> 1
